Workbook

Sheet Assumption
H1: Financial Statement
B2: This Assumption Tab is meant to be as detailed as possible for easier intepretation | H2: Category
H3: Subcategory
A5: x | B5: Income Statement
B6: Line-Item | E6: Assumption
B7: Revenue | E7: Average of past 2 years growth rate and held constant
B8: COGS | E8: Derived from Revenue * (1-Gross Profit Margin)
B9: Gross Profit Margin | E9: Average of past 3 years and held constant
B10: Other Income & Operating Expenses | E10: Average of past 3 years in terms of % of revenue
B11: Fair value loss/gain on biological assets | E11: Inconsistent and assumed zero
B12: Interest Income | E12: Calculated as a percentage of opening cash balance to find out interest rate ->Highly volatile so kept current year interest rate (smaller % = more prudence)
B13: Interest Expense | E13: Calculated as a percentage of opening total debt to infer interest rate -> Used the average of both interest rates and kept constant
B14: Tax Expense | E14: Calculated historical % by taking tax expense / pre-tax profit -> Used the average and kept constant
A17: x | B17: Balance Sheet
B18: Non-Current Assets | E18: Assumption
B19: PPE Depreciation | E19: Found implied depreciation rate (Depreciation of PPE / Opening PPE) -> Used average rate and kept constant
B20: PPE Additions | E20: Calculated additions of PPE as a multiple of depreciation -> A falling trend -> -0.2x YoY
B21: PPE | E21: PPE Closing Balance = PPE Opening Balance - Depreciation + Additions
B22: Intangibles | E22: Amount too small to have any meaningful rate changes -> Held constant based on FY2025 values
B23: ROU Assets (Depreciation and Additions) | E23: Same approach as PPE, but implied depreciation rate and addition multiple too volatile, used FY2025 value and held constant
B24: ROU Assets | E24: ROU Closing = ROU Opening - Depreciation + Additions
B25: Biological Assets (Depreciation and Disposal) | E25: Same approach as PPE but no obvious trend, average of past values used and held constant
B26: Biological Assets | E26: Biological Assets (BA) Closing = BA Opening - Disposals + Additions
B27: Other Non-Current Assets | E27: Projected to grow in line with revenue growth
B29: Current Assets | E29: Assumption
B30: Inventories | E30: Scale with COGS Growth
... B52: Retained Earnings | E52: Retained Earnings (Opening) + Net Income - Dividend Payout (Kept constant at 2025 level) = Closing Retained Earnings
A55: x | B55: Statement of Cash Flows
B56: Most assumptions made in previous statements

Sheet Grouping OR Separating
B2: GROUPING | D2: FY2023A | E2: FY2024A | F2: FY2025A | J2: SEPARATING | L2: FY2023A | M2: FY2024A | N2: FY2025A
B3: Income Statement | J3: Income Statement
B5: Other income | D5: =9162-110 -> 9052 | E5: 11952 | F5: 6829
B6: Fair value (loss)/gain on biological assets | D6: 110 | E6: 502 | F6: -2556
B8: Selling and distribution expenses | D8: -51711 | E8: -69727 | F8: -88063
B9: Administrative expenses | D9: -35872 | E9: -67425 | F9: -88755
B10: Other expenses | D10: -7592 | E10: -6337 | F10: -10846
B11: Operating Expenses | D11: =SUM(D8:D10) -> -95175 | E11: =SUM(E8:E10) -> -143489 | F11: =SUM(F8:F10) -> -187664
B13: Balance Sheet | J13: Balance Sheet
B15: Trade and other receivables | D15: 1130 | E15: 563 | F15: 268 | J15: Short-Term Borrowing | L15: 92934 | M15: 67648 | N15: 91622
B16: Deferred tax assets | D16: 7673 | E16: 8926 | F16: 9371 | J16: Revolving Line of Credit | L16: 14760 | M16: 0 | N16: 0
B17: Other NCAs | D17: =SUM(D15:D16) -> 8803 | E17: =SUM(E15:E16) -> 9489 | F17: =SUM(F15:F16) -> 9639 | J17: Short-Term Borrowing (w/o revolver) | L17: =L15-L16 -> 78174 | M17: =M15-M16 -> 67648 | N17: =N15-N16 -> 91622
B19: Current Tax Assets | D19: 1541 | E19: 4509 | F19: 5446
B20: Derivative Financial Assets | D20: 685 | E20: 893 | F20: 86
B21: Other Investments | D21: 155790 | E21: 99944 | F21: 64037
B22: Other CAs | D22: =SUM(D19:D21) -> 158016 | E22: =SUM(E19:E21) -> 105346 | F22: =SUM(F19:F21) -> 69569
B24: Deferred Tax Liabilities | D24: 7731 | E24: 19161 | F24: 24345
B25: Deferred Income | D25: 6226 | E25: 5955 | F25: 6703
B26: Put Option Liability | D26: - | E26: 36955 | F26: 55833
B27: Other NCLs | D27: =SUM(D24:D26) -> 13957 | E27: =SUM(E24:E26) -> 62071 | F27: =SUM(F24:F26) -> 86881
B29: Deferred Income | D29: 271 | E29: 271 | F29: 943
B30: Derivative Financial Liabilities | D30: 1695 | E30: - | F30: 428
B31: Current Tax Liabilities | D31: - | E31: 648 | F31: 1116
B32: Other CLs | D32: =SUM(D29:D31) -> 1966 | E32: =SUM(E29:E31) -> 919 | F32: =SUM(F29:F31) -> 2487

Sheet 3-Statement
A1: RM'000
D2: FY2023A | E2: FY2024A | F2: FY2025A | G2: FY2026E | H2: FY2027E | I2: FY2028E | J2: FY2029E | K2: FY2030E
A3: x | B3: Income Statement
B4: Revenue | D4: 629691 | E4: 810411 | F4: 981181 | G4: =F4*(1+G21) -> 1225356.8 | H4: =G4*(1+H21) -> 1530298 | I4: =H4*(1+I21) -> 1911126.5 | J4: =I4*(1+J21) -> 2386727.7 | K4: =J4*(1+K21) -> 2980686.5
B5: (-) COGS | D5: -480038 | E5: -594368 | F5: -665947 | G5: =-G4*(1-G23) -> -888168.97 | H5: =-H4*(1-H23) -> -1109197.9 | I5: =-I4*(1-I23) -> -1385231.8 | J5: =-J4*(1-J23) -> -1729959.3 | K5: =-K4*(1-K23) -> -2160475.4
B6: Gross Profit | D6: =SUM(D4:D5) -> 149653 | E6: =SUM(E4:E5) -> 216043 | F6: =SUM(F4:F5) -> 315234 | G6: =SUM(G4:G5) -> 337187.83 | H6: =SUM(H4:H5) -> 421100.08 | I6: =SUM(I4:I5) -> 525894.66 | J6: =SUM(J4:J5) -> 656768.31 | K6: =SUM(K4:K5) -> 820211.07
B7: Other Income | D7: ='Grouping OR Separating'!D5 -> 9052 | E7: ='Grouping OR Separating'!E5 -> 11952 | F7: ='Grouping OR Separating'!F5 -> 6829 | G7: =G4*G24 -> 14738.329 | H7: =H4*H24 -> 18406.096 | I7: =I4*I24 -> 22986.62 | J7: =J4*J24 -> 28707.049 | K7: =K4*K24 -> 35851.058
B8: Operating Expenses | D8: ='Grouping OR Separating'!D11 -> -95175 | E8: ='Grouping OR Separating'!E11 -> -143489 | F8: ='Grouping OR Separating'!F11 -> -187664 | G8: =-G4*G25 -> -212177.07 | H8: =-H4*H25 -> -264979.26 | I8: =-I4*I25 -> -330921.76 | J8: =-J4*J25 -> -413274.64 | K8: =-K4*K25 -> -516121.78
B9: Fair value (loss)/gain on biological assets | D9: ='Grouping OR Separating'!D6 -> 110 | E9: ='Grouping OR Separating'!E6 -> 502 | F9: ='Grouping OR Separating'!F6 -> -2556 | G9: 0 | H9: 0 | I9: 0 | J9: 0 | K9: 0
B10: Operating Profit (EBIT) | D10: =SUM(D6:D9) -> 63640 | E10: =SUM(E6:E9) -> 85008 | F10: =SUM(F6:F9) -> 131843 | G10: =SUM(G6:G9) -> 139749.09 | H10: =SUM(H6:H9) -> 174526.91 | I10: =SUM(I6:I9) -> 217959.52 | J10: =SUM(J6:J9) -> 272200.72 | K10: =SUM(K6:K9) -> 339940.34
B12: Interest Income | D12: 473 | E12: 937 | F12: 1062 | G12: =G26*F61 -> 1073.2833 | H12: =H26*G61 -> 1118.6144 | I12: =I26*H61 -> 1396.9918 | J12: =J26*I61 -> 1744.6459 | K12: =K26*J61 -> 2178.8168
B13: Interest Expense | D13: -11939 | E13: -16880 | F13: -17672 | G13: =G27*-F91 -> -19149.26 | H13: =H27*-G91 -> -22261.021 | I13: =I27*-H91 -> -26591.073 | J13: =J27*-I91 -> -30517.195 | K13: =K27*-J91 -> -33845.68
B14: Pre-Tax Profit (EBT) | D14: =D10+D12+D13 -> 52174 | E14: =E10+E12+E13 -> 69065 | F14: =F10+F12+F13 -> 115233 | G14: =G10+G12+G13 -> 121673.11 | H14: =H10+H12+H13 -> 153384.51 | I14: =I10+I12+I13 -> 192765.44 | J14: =J10+J12+J13 -> 243428.17 | K14: =K10+K12+K13 -> 308273.48
B16: Tax Expense | D16: -2240 | E16: -5784 | F16: -7918 | G16: =-G14*G28 -> -7924.7079 | H16: =-H14*H28 -> -9990.1074 | I16: =-I14*I28 -> -12555.032 | J16: =-J14*J28 -> -15854.754 | K16: =-K14*K28 -> -20078.202
B17: Net Income (Earnings) | D17: =D14+D16 -> 49934 | E17: =E14+E16 -> 63281 | F17: =F14+F16 -> 107315 | G17: =G14+G16 -> 113748.4 | H17: =H14+H16 -> 143394.4 | I17: =I14+I16 -> 180210.41 | J17: =J14+J16 -> 227573.42 | K17: =K14+K16 -> 288195.28
A20: x | B20: Assumptions
B21: Revenue Growth | E21: =E4/D4-1 -> 0.28699791 | F21: =F4/E4-1 -> 0.21072024 | G21: =AVERAGE(E21:F21) -> 0.24885907 | H21: =G21 -> 0.24885907 | I21: =H21 -> 0.24885907 | J21: =I21 -> 0.24885907 | K21: =J21 -> 0.24885907
B22: COGS Growth | E22: =E5/D5-1 -> 0.23816864 | F22: =F5/E5-1 -> 0.12042876 | G22: =G5/F5-1 -> 0.33369317 | H22: =H5/G5-1 -> 0.24885907 | I22: =I5/H5-1 -> 0.24885907 | J22: =J5/I5-1 -> 0.24885907 | K22: =K5/J5-1 -> 0.24885907
B23: Gross Profit Margin | D23: =D6/D4 -> 0.23766101 | E23: =E6/E4 -> 0.26658449 | F23: =F6/F4 -> 0.32128017 | G23: =AVERAGE(D23:F23) -> 0.27517522 | H23: =G23 -> 0.27517522 | I23: =H23 -> 0.27517522 | J23: =I23 -> 0.27517522 | K23: =J23 -> 0.27517522
B24: Other Income - % of Revenue | D24: =D7/D4 -> 0.014375305 | E24: =E7/E4 -> 0.014748072 | F24: =F7/F4 -> 0.0069599799 | G24: =AVERAGE(D24:F24) -> 0.012027786 | H24: =G24 -> 0.012027786 | I24: =H24 -> 0.012027786 | J24: =I24 -> 0.012027786 | K24: =J24 -> 0.012027786
B25: Operating Expenses - % of Revenue | D25: =-D8/D4 -> 0.15114556 | E25: =-E8/E4 -> 0.17705707 | F25: =-F8/F4 -> 0.19126339 | G25: =AVERAGE(D25:F25) -> 0.17315534 | H25: =G25 -> 0.17315534 | I25: =H25 -> 0.17315534 | J25: =I25 -> 0.17315534 | K25: =J25 -> 0.17315534
B26: Interest Income - % of Cash | E26: =E12/D61 -> 0.040792338 | F26: =F12/E61 -> 0.018257775 | G26: =F26 -> 0.018257775 | H26: =G26 -> 0.018257775 | I26: =H26 -> 0.018257775 | J26: =I26 -> 0.018257775 | K26: =J26 -> 0.018257775
B27: Interest Expense - % of Total Debt | E27: =-E13/D91 -> 0.04869198 | F27: =-F13/E91 -> 0.041024689 | G27: =AVERAGE(D27:F27) -> 0.044858334 | H27: =G27 -> 0.044858334 | I27: =H27 -> 0.044858334 | J27: =I27 -> 0.044858334 | K27: =J27 -> 0.044858334
B28: Tax Rate | D28: =-D16/D14 -> 0.042933262 | E28: =-E16/E14 -> 0.083747195 | F28: =-F16/F14 -> 0.068712955 | G28: =AVERAGE(D28:F28) -> 0.065131137 | H28: =G28 -> 0.065131137 | I28: =H28 -> 0.065131137 | J28: =I28 -> 0.065131137 | K28: =J28 -> 0.065131137
B30: Depreciation of PPE | D30: -31064 | E30: -40165 | F30: -48080 | G30: =-F52*G32 -> -49873.454 | H30: =-G52*H32 -> -55043.308 | I30: =-H52*I32 -> -59679.835 | J30: =-I52*J32 -> -63547.618 | K30: =-J52*K32 -> -66431.636
B31: Additions of PPE | D31: 117834 | E31: 105976 | F31: 109010 | G31: =-G30*G33 -> 103101.54 | H31: =-H30*H33 -> 102780.33 | I31: =-I30*I33 -> 99501.974 | J31: =-J30*J33 -> 93241.061 | K31: =-K30*K33 -> 84186.347
B32: Implied Depreciation Rate (PPE) | E32: =-E30/D52 -> 0.097049492 | F32: =-F30/E52 -> 0.097203381 | G32: =AVERAGE(E32:F32) -> 0.097126437 | H32: =G32 -> 0.097126437 | I32: =H32 -> 0.097126437 | J32: =I32 -> 0.097126437 | K32: =J32 -> 0.097126437
B33: Additions as multiple of Depreciation | D33: =D31/-D30 -> 3.7932655 | E33: =E31/-E30 -> 2.6385161 | F33: =F31/-F30 -> 2.2672629 | G33: =F33-0.2 -> 2.0672629 | H33: =G33-0.2 -> 1.8672629 | I33: =H33-0.2 -> 1.6672629 | J33: =I33-0.2 -> 1.4672629 | K33: =J33-0.2 -> 1.2672629
B35: Amortization of Intangible Assets | D35: -235 | E35: -263 | F35: -274 | G35: =F35 -> -274 | H35: =G35 -> -274 | I35: =H35 -> -274 | J35: =I35 -> -274 | K35: =J35 -> -274
B36: Purchases of Intangibles | D36: 324.495 | E36: 1124 | F36: 623 | G36: =F36 -> 623 | H36: =G36 -> 623 | I36: =H36 -> 623 | J36: =I36 -> 623 | K36: =J36 -> 623
B38: Depreciation of ROU Assets | D38: -1928 | E38: -8158 | F38: -10163 | G38: =-F54*G40 -> -11188.689 | H38: =-G54*H40 -> -12834.024 | I38: =-H54*I40 -> -14721.313 | J38: =-I54*J40 -> -16886.133 | K38: =-J54*K40 -> -19369.298
B39: Additions of ROU Assets | D39: 6888 | E39: 11952 | F39: 15034 | G39: =-G38*G41 -> 16551.288 | H39: =-H38*H41 -> 18985.213 | I39: =-I38*I41 -> 21777.055 | J39: =-J38*J41 -> 24979.447 | K39: =-K38*K41 -> 28652.762
B40: Implied Depreciation Rate (ROU) | E40: =-E38/D54 -> 0.42097115 | F40: =-F38/E54 -> 0.30681681 | G40: =F40 -> 0.30681681 | H40: =G40 -> 0.30681681 | I40: =H40 -> 0.30681681 | J40: =I40 -> 0.30681681 | K40: =J40 -> 0.30681681
B41: Additions as multiple of Depreciation | D41: =D39/-D38 -> 3.5726141 | E41: =E39/-E38 -> 1.465065 | F41: =F39/-F38 -> 1.4792876 | G41: =F41 -> 1.4792876 | H41: =G41 -> 1.4792876 | I41: =H41 -> 1.4792876 | J41: =I41 -> 1.4792876 | K41: =J41 -> 1.4792876
B43: Biological Asset Disposal | D43: =-(8209+294) -> -8503 | E43: -5776 | F43: -6025 | G43: =-F55*G45 -> -6767.2582 | H43: =-G55*H45 -> -7753.1927 | I43: =-H55*I45 -> -8882.7699 | J43: =-I55*J45 -> -10176.917 | K43: =-J55*K45 -> -11659.611
B44: Additions of Biological Asset | D44: 29364 | E44: 23538 | F44: 24323 | G44: =-G43*G46 -> 27448.51 | H44: =-H43*H46 -> 31447.535 | I44: =-I43*I46 -> 36029.185 | J44: =-J43*J46 -> 41278.344 | K44: =-K43*K46 -> 47292.263
B45: Implied Disposal Rate (Biological Assets) | E45: =-E43/D55 -> 0.0501415 | F45: =-'3-Statement'!F43/'3-Statement'!E55 -> 0.045204226 | G45: =AVERAGE(E45:F45) -> 0.047672863 | H45: =G45 -> 0.047672863 | I45: =H45 -> 0.047672863 | J45: =I45 -> 0.047672863 | K45: =J45 -> 0.047672863
B46: Additions as multiple of Disposal | D46: =D44/-D43 -> 3.4533694 | E46: =E44/-E43 -> 4.0751385 | F46: =F44/-F43 -> 4.0370124 | G46: =AVERAGE(E46:F46) -> 4.0560755 | H46: =G46 -> 4.0560755 | I46: =H46 -> 4.0560755 | J46: =I46 -> 4.0560755 | K46: =J46 -> 4.0560755
B48: Memo: Total CAPEX | D48: =D31+D36+D39+D44 -> 154410.49 | E48: =E31+E36+E39+E44 -> 142590 | F48: =F31+F36+F39+F44 -> 148990 | G48: =G31+G36+G39+G44 -> 147724.34 | H48: =H31+H36+H39+H44 -> 153836.08 | I48: =I31+I36+I39+I44 -> 157931.21 | J48: =J31+J36+J39+J44 -> 160121.85 | K48: =K31+K36+K39+K44 -> 160754.37
A51: x | B51: Balance Sheet
...

Sheet DCF
A1: RM'000
D2: FY2025A | E2: FY2026E | F2: FY2027E | G2: FY2028E | H2: FY2029E | I2: FY2030E | J2: Terminal Year (Normalized)
A3: x | B3: Extracted From 3-Statement Model | L3: Farm Fresh in FY2030 is in its high-growth phase
B4: EBIT | D4: ='3-Statement'!F10 -> 131843 | E4: ='3-Statement'!G10 -> 139749.09 | F4: ='3-Statement'!H10 -> 174526.91 | G4: ='3-Statement'!I10 -> 217959.52 | H4: ='3-Statement'!J10 -> 272200.72 | I4: ='3-Statement'!K10 -> 339940.34 | J4: =I4*(1+D49) -> 354217.84 | L4: A DCF's terminal value assumes company grows at constant rate forever
B5: D&A | D5: =-('3-Statement'!F30+'3-Statement'!F35+'3-Statement'!F38) -> 58517 | E5: ='3-Statement'!G127 -> 61336.143 | F5: ='3-Statement'!H127 -> 68151.333 | G5: ='3-Statement'!I127 -> 74675.148 | H5: ='3-Statement'!J127 -> 80707.751 | I5: ='3-Statement'!K127 -> 86074.934 | J5: =I5*(1+D49) -> 89690.081 | L5: So, we have to create a normalized terminal year as a proxy for Farm Fresh in mature, steady state
B6: EBITDA | D6: =D4+D5 -> 190360 | E6: =E4+E5 -> 201085.23 | F6: =F4+F5 -> 242678.25 | G6: =G4+G5 -> 292634.67 | H6: =H4+H5 -> 352908.47 | I6: =I4+I5 -> 426015.28 | J6: =J4+J5 -> 443907.92
L7: D&A = CAPEX because in steady state, company stopped expanding and scaling capacity
B8: Tax Rate | C8: ='3-Statement'!G28 -> 0.065131137 | L8: Company is simply replacing worn-out fixed assets
B10: CAPEX | E10: ='3-Statement'!G48 -> 147724.34 | F10: ='3-Statement'!H48 -> 153836.08 | G10: ='3-Statement'!I48 -> 157931.21 | H10: ='3-Statement'!J48 -> 160121.85 | I10: ='3-Statement'!K48 -> 160754.37 | J10: =J5 -> 89690.081 | L10: Change in NWC also has to get scaled down to grow at steady-state growth
B12: Inventories | E12: ='3-Statement'!G128 -> -58507.091 | F12: ='3-Statement'!H128 -> -58192.98 | G12: ='3-Statement'!I128 -> -72674.831 | H12: ='3-Statement'!J128 -> -90760.622 | I12: ='3-Statement'!K128 -> -113347.23
B13: Receivables | E13: ='3-Statement'!G129 -> -51430.461 | F13: ='3-Statement'!H129 -> -64229.397 | G13: ='3-Statement'!I129 -> -80213.466 | H13: ='3-Statement'!J129 -> -100175.31 | I13: ='3-Statement'!K129 -> -125104.85
B14: Other Current Assets | E14: ='3-Statement'!G130 -> -17312.877 | F14: ='3-Statement'!H130 -> -21621.343 | G14: ='3-Statement'!I130 -> -27002.011 | H14: ='3-Statement'!J130 -> -33721.706 | I14: ='3-Statement'!K130 -> -42113.659
B15: Payables | E15: ='3-Statement'!G131 -> 35598.054 | F15: ='3-Statement'!H131 -> 35406.936 | G15: ='3-Statement'!I131 -> 44218.273 | H15: ='3-Statement'!J131 -> 55222.392 | I15: ='3-Statement'!K131 -> 68964.985
B16: Other Current Liabilities | E16: ='3-Statement'!G132 -> 829.89491 | F16: ='3-Statement'!H132 -> 825.4394 | G16: ='3-Statement'!I132 -> 1030.8575 | H16: ='3-Statement'!J132 -> 1287.3957 | I16: ='3-Statement'!K132 -> 1607.7758
B17: Change in NWC | E17: =SUM(E12:E16) -> -90822.48 | F17: =SUM(F12:F16) -> -107811.35 | G17: =SUM(G12:G16) -> -134641.18 | H17: =SUM(H12:H16) -> -168147.86 | I17: =SUM(I12:I16) -> -209992.97 | J17: =I17*(D49/'3-Statement'!G21) -> -35440.56
R18: =D6/-'3-Statement'!F13 -> 10.771842
A20: x | B20: WACC
B21: Debt
B22: Interest Expense | D22: ='3-Statement'!F13 -> -17672
B23: Total Debt | D23: ='3-Statement'!F91 -> 426883
B24: Cost of Debt | D24: =-D22/D23 -> 0.04139776 | N24: ='3-Statement'!D10-('3-Statement'!D30+'3-Statement'!D35+'3-Statement'!D38) -> 96867 | O24: ='3-Statement'!E10-('3-Statement'!E30+'3-Statement'!E35+'3-Statement'!E38) -> 133594 | P24: =D6 -> 190360 | Q24: =E6 -> 201085.23 | R24: =F6 -> 242678.25 | S24: =G6 -> 292634.67 | T24: =H6 -> 352908.47 | U24: =I6 -> 426015.28
N25: ='3-Statement'!D91 -> 346669 | O25: ='3-Statement'!E91 -> 430765 | P25: ='3-Statement'!F91 -> 426883 | Q25: ='3-Statement'!G91 -> 496251.61 | R25: ='3-Statement'!H91 -> 592778.87 | S25: ='3-Statement'!I91 -> 680301.57 | T25: ='3-Statement'!J91 -> 754501.5 | U25: ='3-Statement'!K91 -> 810787.94
B26: Equity | N26: =N24/-'3-Statement'!D13 -> 8.1134936 | O26: =O24/-'3-Statement'!E13 -> 7.9143365 | P26: =P24/-'3-Statement'!F13 -> 10.771842 | Q26: =Q24/-'3-Statement'!G13 -> 10.50094 | R26: =R24/-'3-Statement'!H13 -> 10.901488 | S26: =S24/-'3-Statement'!I13 -> 11.004997 | T26: =T24/-'3-Statement'!J13 -> 11.56425 | U26: =U24/-'3-Statement'!K13 -> 12.586991
B27: Risk-Free Rate (10y government bond yield) | D27: 0.03747 | F27: https://www.worldgovernmentbonds.com/country/malaysia/
B28: Levered Beta of Farm Fresh (1Y) | D28: 0.74 | F28: https://www.tradingview.com/symbols/MYX-FFB/
B29: Equity Risk Premium | D29: 0.0504 | F29: https://pages.stern.nyu.edu/~adamodar/New_Home_Page/datafile/ctryprem.html
B30: Cost of Equity | D30: =D27+D28*D29 -> 0.074766 | F30: CAPM Model
B32: Share
B33: Market Capitalization (as of 11/8) | D33: 4184000 | F33: https://finance.yahoo.com/quote/5306.KL/
B34: Total Capital Structure | D34: =D33+D23 -> 4610883
B35: Share of Debt | D35: =D23/D34 -> 0.092581616
B36: Share of Equity | D36: =D33/D34 -> 0.90741838
B38: WACC | D38: =(D36*D30)+D35*(D24*(1-C8)) -> 0.071427088
A41: x | B41: FCF Calculation
B42: EBIT | E42: =E4 -> 139749.09 | F42: =F4 -> 174526.91 | G42: =G4 -> 217959.52 | H42: =H4 -> 272200.72 | I42: =I4 -> 339940.34 | J42: =J4 -> 354217.84
A43: (-) | B43: Taxes | E43: =(E42*$C$8)*-1 -> -9102.0169 | F43: =(F42*$C$8)*-1 -> -11367.136 | G43: =(G42*$C$8)*-1 -> -14195.951 | H43: =(H42*$C$8)*-1 -> -17728.743 | I43: =(I42*$C$8)*-1 -> -22140.701 | J43: =-J42*C8 -> -23070.611
A44: (+) | B44: D&A | E44: =E5 -> 61336.143 | F44: =F5 -> 68151.333 | G44: =G5 -> 74675.148 | H44: =H5 -> 80707.751 | I44: =I5 -> 86074.934 | J44: =J5 -> 89690.081
A45: (-) | B45: CAPEX | E45: =(E10)*-1 -> -147724.34 | F45: =(F10)*-1 -> -153836.08 | G45: =(G10)*-1 -> -157931.21 | H45: =(H10)*-1 -> -160121.85 | I45: =(I10)*-1 -> -160754.37 | J45: =-J10 -> -89690.081
A46: (-) | B46: Change in NWC | E46: =E17 -> -90822.48 | F46: =F17 -> -107811.35 | G46: =G17 -> -134641.18 | H46: =H17 -> -168147.86 | I46: =I17 -> -209992.97 | J46: =J17 -> -35440.56
B47: Annual Unlevered FCF | E47: =SUM(E42:E46) -> -46563.608 | F47: =SUM(F42:F46) -> -30336.311 | G47: =SUM(G42:G46) -> -14133.676 | H47: =SUM(H42:H46) -> 6910.0233 | I47: =SUM(I42:I46) -> 33127.228 | J47: =SUM(J42:J46) -> 295706.67
...
